[
  {
    "dateRange": {
      "start": "2024-05-13",
      "end": "2024-05-13"
    },
    "url": "https://api.github.com/search/issues?q=commenter:diberry+created:2024-05-13..2024-05-13",
    "user": "diberry",
    "results": {
      "total_count": 0,
      "incomplete_results": false,
      "items": []
    }
  },
  {
    "dateRange": {
      "start": "2024-05-13",
      "end": "2024-05-13"
    },
    "url": "https://api.github.com/search/issues?q=commenter:dfberry+created:2024-05-13..2024-05-13",
    "user": "dfberry",
    "results": {
      "total_count": 0,
      "incomplete_results": false,
      "items": []
    }
  },
  {
    "dateRange": {
      "start": "2024-05-13",
      "end": "2024-05-13"
    },
    "url": "https://api.github.com/search/issues?q=mentions:diberry+created:2024-05-13..2024-05-13",
    "user": "diberry",
    "results": {
      "total_count": 0,
      "incomplete_results": false,
      "items": []
    }
  },
  {
    "dateRange": {
      "start": "2024-05-13",
      "end": "2024-05-13"
    },
    "url": "https://api.github.com/search/issues?q=mentions:dfberry+created:2024-05-13..2024-05-13",
    "user": "dfberry",
    "results": {
      "total_count": 0,
      "incomplete_results": false,
      "items": []
    }
  },
  {
    "dateRange": {
      "start": "2024-05-13",
      "end": "2024-05-13"
    },
    "url": "https://api.github.com/search/issues?q=involves:diberry+created:2024-05-13..2024-05-13",
    "user": "diberry",
    "results": {
      "total_count": 1,
      "incomplete_results": false,
      "items": [
        {
          "url": "https://api.github.com/repos/Azure-Samples/ai-rag-chat-evaluator/issues/87",
          "repository_url": "https://api.github.com/repos/Azure-Samples/ai-rag-chat-evaluator",
          "labels_url": "https://api.github.com/repos/Azure-Samples/ai-rag-chat-evaluator/issues/87/labels{/name}",
          "comments_url": "https://api.github.com/repos/Azure-Samples/ai-rag-chat-evaluator/issues/87/comments",
          "events_url": "https://api.github.com/repos/Azure-Samples/ai-rag-chat-evaluator/issues/87/events",
          "html_url": "https://github.com/Azure-Samples/ai-rag-chat-evaluator/issues/87",
          "id": 2293980491,
          "node_id": "I_kwDOKv-Fzc6Iu11L",
          "number": 87,
          "title": "Credential failure on evaluate script",
          "user": {
            "login": "diberry",
            "id": 41597107,
            "node_id": "MDQ6VXNlcjQxNTk3MTA3",
            "avatar_url": "https://avatars.githubusercontent.com/u/41597107?v=4",
            "gravatar_id": "",
            "url": "https://api.github.com/users/diberry",
            "html_url": "https://github.com/diberry",
            "followers_url": "https://api.github.com/users/diberry/followers",
            "following_url": "https://api.github.com/users/diberry/following{/other_user}",
            "gists_url": "https://api.github.com/users/diberry/gists{/gist_id}",
            "starred_url": "https://api.github.com/users/diberry/starred{/owner}{/repo}",
            "subscriptions_url": "https://api.github.com/users/diberry/subscriptions",
            "organizations_url": "https://api.github.com/users/diberry/orgs",
            "repos_url": "https://api.github.com/users/diberry/repos",
            "events_url": "https://api.github.com/users/diberry/events{/privacy}",
            "received_events_url": "https://api.github.com/users/diberry/received_events",
            "type": "User",
            "site_admin": false
          },
          "labels": [],
          "state": "open",
          "locked": false,
          "assignee": null,
          "assignees": [],
          "milestone": null,
          "comments": 3,
          "created_at": "2024-05-13T22:54:01Z",
          "updated_at": "2024-05-13T23:39:37Z",
          "closed_at": null,
          "author_association": "CONTRIBUTOR",
          "active_lock_reason": null,
          "body": "<!--\r\nIF SUFFICIENT INFORMATION IS NOT PROVIDED VIA THE FOLLOWING TEMPLATE THE ISSUE MIGHT BE CLOSED WITHOUT FURTHER CONSIDERATION OR INVESTIGATION\r\n-->\r\n> Please provide us with the following information:\r\n> ---------------------------------------------------------------\r\n\r\n### This issue is for a: (mark with an `x`)\r\n```\r\n- [ X] bug report -> please search issues before submitting\r\n- [ ] feature request\r\n- [ ] documentation issue or request\r\n- [ ] regression (a behavior that used to work and stopped in a new release)\r\n```\r\n\r\n### Minimal steps to reproduce\r\n>\r\n\r\n1. azd up\r\n2. Look at .env\r\n\r\n```ini\r\nAZURE_ENV_NAME=\"dfberry-py-evaluations\"\r\nAZURE_LOCATION=\"swedencentral\"\r\nAZURE_OPENAI_EVAL_DEPLOYMENT=\"eval\"\r\nAZURE_OPENAI_RESOURCE_GROUP=\"dfberry-py-evaluationstrvkoypjkqie6-rg\"\r\nAZURE_OPENAI_SERVICE=\"dfberry-py-evaluationstrvkoypjkqie6-openai\"\r\nAZURE_RESOURCE_GROUP=\"dfberry-py-evaluationstrvkoypjkqie6-rg\"\r\nAZURE_SUBSCRIPTION_ID=\"2123cb08-23fa-4a80-afec-4ec9e015433f\"\r\nAZURE_TENANT_ID=\"72f988bf-86f1-41af-91ab-2d7cd011db47\"\r\nOPENAI_GPT_MODEL=\"gpt-4\"\r\nOPENAI_HOST=\"azure\"\r\nOPENAI_KEY=\"\"\r\nOPENAI_ORGANIZATION=\"\"\r\n```\r\n\r\n3. Run script: `python3 -m scripts generate --output=my_input/qa.jsonl --numquestions=14 --persource=2`\r\n4. Run Script: `python3 -m scripts evaluate --config=my_config.json --numquestions=14` with the following my_config.json\r\n\r\n```\r\n{\r\n    \"testdata_path\": \"my_input/qa.jsonl\",\r\n    \"results_dir\": \"my_results/experiment_refined\",\r\n    \"target_url\": \"https://app-backend-uchshrwcihlhg.azurewebsites.net/chat\",\r\n    \"target_parameters\": {\r\n        \"overrides\": {\r\n            \"semantic_ranker\": false,\r\n            \"prompt_template\": \"<READFILE>my_input/prompt_refined.txt\"\r\n        }\r\n    }\r\n}\r\n```\r\n\r\n5. Get the following error: \r\n\r\n```console\r\ndiberry ➜ /workspaces/ai-rag-chat-evaluator (main) $ python3 -m scripts evaluate --config=my_config.json --numquestions=14\r\n[22:43:56] INFO     Running evaluation from config                                               evaluate.py:207\r\n                    /workspaces/ai-rag-chat-evaluator/my_config.json                                            \r\n           INFO     Replaced prompt_template in config with contents of                          evaluate.py:201\r\n                    my_input/prompt_refined.txt                                                                 \r\n           INFO     Using Azure OpenAI Service with Azure Developer CLI Credential           service_setup.py:27\r\n           INFO     Running evaluation using data from                                            evaluate.py:77\r\n                    /workspaces/ai-rag-chat-evaluator/my_input/qa.jsonl                                         \r\n           INFO     Limiting evaluation to 14 questions                                           evaluate.py:80\r\n           INFO     Sending a test question to the target to ensure it is running...              evaluate.py:83\r\n[22:44:43] INFO     Successfully received response from target for question: \"What information is evaluate.py:92\r\n                    in your knowledge base?\"                                                                    \r\n                    \"answer\": \"Our knowledge base includes information on custome...\"                           \r\n                    \"context\": \"role_library.pdf#page=31:  Responsibilities: · Mai...\"                          \r\n           INFO     Sending a test chat completion to the GPT deployment to ensure it is         evaluate.py:102\r\n                    running...                                                                                  \r\n[22:44:46] INFO     Successfully received response from GPT: \"Hello! How can I assist you        evaluate.py:109\r\n                    today?\"                                                                                     \r\n           INFO     Starting evaluation...                                                       evaluate.py:114\r\n[22:45:00] WARNING  DefaultAzureCredential failed to retrieve a token from the included           chained.py:123\r\n                    credentials.                                                                                \r\n                    Attempted credentials:                                                                      \r\n                            EnvironmentCredential: EnvironmentCredential authentication                         \r\n                    unavailable. Environment variables are not fully configured.                                \r\n                    Visit https://aka.ms/azsdk/python/identity/environmentcredential/troubleshoot               \r\n                    to troubleshoot this issue.                                                                 \r\n                            ManagedIdentityCredential: ManagedIdentityCredential authentication                 \r\n                    unavailable. The requested identity has not been assigned to this resource.                 \r\n                    Error: Unexpected response \"{'error': 'invalid_request', 'error_description':               \r\n                    'Identity not found'}\"                                                                      \r\n                            SharedTokenCacheCredential: SharedTokenCacheCredential authentication               \r\n                    unavailable. No accounts were found in the cache.                                           \r\n                            AzureCliCredential: Azure CLI not found on path                                     \r\n                            AzurePowerShellCredential: PowerShell is not installed                              \r\n                            AzureDeveloperCliCredential:                                                        \r\n                    {\"type\":\"consoleMessage\",\"timestamp\":\"2024-05-13T22:45:00.062907884Z\",\"data\":               \r\n                    {\"message\":\"\\nERROR: fetching token: failed to authenticate:\\n(invalid_scope)               \r\n                    AADSTS70011: The provided request must include a 'scope' input parameter. The               \r\n                    provided value for the input parameter 'scope' is not valid. The scope                      \r\n                    https://cognitiveservices.azure.com/ openid offline_access profile is not                   \r\n                    valid. The scope format is invalid. Scope must be in a valid URI form                       \r\n                    \\u003chttps://example/scope\\u003e or a valid Guid \\u003cguid/scope\\u003e.                   \r\n                    Trace ID: ba0a99de-13ba-4ae6-975c-b465e1195500 Correlation ID:                              \r\n                    6906592c-47f3-4e5b-9d23-8e221afc8ea6 Timestamp: 2024-05-13 22:45:00Z\\n\\n\"}}                 \r\n                                                                                                                \r\n                    To mitigate this issue, please refer to the troubleshooting guidelines here                 \r\n                    at https://aka.ms/azsdk/python/identity/defaultazurecredential/troubleshoot.                \r\n[22:45:01] WARNING  DefaultAzureCredential failed to retrieve a token from the included           chained.py:123\r\n                    credentials.                                                                                \r\n                    Attempted credentials:                                                                      \r\n                            EnvironmentCredential: EnvironmentCredential authentication                         \r\n                    unavailable. Environment variables are not fully configured.                                \r\n                    Visit https://aka.ms/azsdk/python/identity/environmentcredential/troubleshoot               \r\n                    to troubleshoot this issue.                                                                 \r\n                            ManagedIdentityCredential: ManagedIdentityCredential authentication                 \r\n                    unavailable. The requested identity has not been assigned to this resource.                 \r\n                    Error: Unexpected response \"{'error': 'invalid_request', 'error_description':               \r\n                    'Identity not found'}\"                                                                      \r\n                            SharedTokenCacheCredential: SharedTokenCacheCredential authentication               \r\n                    unavailable. No accounts were found in the cache.                                           \r\n                            AzureCliCredential: Azure CLI not found on path                                     \r\n                            AzurePowerShellCredential: PowerShell is not installed                              \r\n                            AzureDeveloperCliCredential:                                                        \r\n                    {\"type\":\"consoleMessage\",\"timestamp\":\"2024-05-13T22:45:01.462735824Z\",\"data\":               \r\n                    {\"message\":\"\\nERROR: fetching token: failed to authenticate:\\n(invalid_scope)               \r\n                    AADSTS70011: The provided request must include a 'scope' input parameter. The               \r\n                    provided value for the input parameter 'scope' is not valid. The scope                      \r\n                    https://cognitiveservices.azure.com/ openid offline_access profile is not                   \r\n                    valid. The scope format is invalid. Scope must be in a valid URI form                       \r\n                    \\u003chttps://example/scope\\u003e or a valid Guid \\u003cguid/scope\\u003e.                   \r\n                    Trace ID: f46f2ce6-c2df-41f5-8a8b-e288cbcd5600 Correlation ID:                              \r\n                    a866b280-de86-489b-8b32-6decb8b920a1 Timestamp: 2024-05-13 22:45:01Z\\n\\n\"}}                 \r\n                                                                                                                \r\n                    To mitigate this issue, please refer to the troubleshooting guidelines here                 \r\n                    at https://aka.ms/azsdk/python/identity/defaultazurecredential/troubleshoot.                \r\n[22:45:02] WARNING  DefaultAzureCredential failed to retrieve a token from the included           chained.py:123\r\n                    credentials.                                                                                \r\n                    Attempted credentials:                                                                      \r\n                            EnvironmentCredential: EnvironmentCredential authentication                         \r\n                    unavailable. Environment variables are not fully configured.                                \r\n                    Visit https://aka.ms/azsdk/python/identity/environmentcredential/troubleshoot               \r\n                    to troubleshoot this issue.                                                                 \r\n                            ManagedIdentityCredential: ManagedIdentityCredential authentication                 \r\n                    unavailable. The requested identity has not been assigned to this resource.                 \r\n                    Error: Unexpected response \"{'error': 'invalid_request', 'error_description':               \r\n                    'Identity not found'}\"                                                                      \r\n                            SharedTokenCacheCredential: SharedTokenCacheCredential authentication               \r\n                    unavailable. No accounts were found in the cache.                                           \r\n                            AzureCliCredential: Azure CLI not found on path                                     \r\n                            AzurePowerShellCredential: PowerShell is not installed                              \r\n                            AzureDeveloperCliCredential:                                                        \r\n                    {\"type\":\"consoleMessage\",\"timestamp\":\"2024-05-13T22:45:02.186514156Z\",\"data\":               \r\n                    {\"message\":\"\\nERROR: fetching token: failed to authenticate:\\n(invalid_scope)               \r\n                    AADSTS70011: The provided request must include a 'scope' input parameter. The               \r\n                    provided value for the input parameter 'scope' is not valid. The scope                      \r\n                    https://cognitiveservices.azure.com/ openid offline_access profile is not                   \r\n                    valid. The scope format is invalid. Scope must be in a valid URI form                       \r\n                    \\u003chttps://example/scope\\u003e or a valid Guid \\u003cguid/scope\\u003e.                   \r\n                    Trace ID: 0d826a6e-4544-4706-8e05-8cd318e55c00 Correlation ID:                              \r\n                    c68a6fef-59ca-4916-b452-012072a747e2 Timestamp: 2024-05-13 22:45:02Z\\n\\n\"}}                 \r\n                                                                                                                \r\n                    To mitigate this issue, please refer to the troubleshooting guidelines here                 \r\n                    at https://aka.ms/azsdk/python/identity/defaultazurecredential/troubleshoot.                \r\n           WARNING  DefaultAzureCredential failed to retrieve a token from the included           chained.py:123\r\n                    credentials.                                                                                \r\n                    Attempted credentials:                                                                      \r\n                            EnvironmentCredential: EnvironmentCredential authentication                         \r\n                    unavailable. Environment variables are not fully configured.                                \r\n                    Visit https://aka.ms/azsdk/python/identity/environmentcredential/troubleshoot               \r\n                    to troubleshoot this issue.                                                                 \r\n                            ManagedIdentityCredential: ManagedIdentityCredential authentication                 \r\n                    unavailable. The requested identity has not been assigned to this resource.                 \r\n                    Error: Unexpected response \"{'error': 'invalid_request', 'error_description':               \r\n                    'Identity not found'}\"                                                                      \r\n                            SharedTokenCacheCredential: SharedTokenCacheCredential authentication               \r\n                    unavailable. No accounts were found in the cache.                                           \r\n                            AzureCliCredential: Azure CLI not found on path                                     \r\n                            AzurePowerShellCredential: PowerShell is not installed                              \r\n                            AzureDeveloperCliCredential:                                                        \r\n                    {\"type\":\"consoleMessage\",\"timestamp\":\"2024-05-13T22:45:02.420259563Z\",\"data\":               \r\n                    {\"message\":\"\\nERROR: fetching token: failed to authenticate:\\n(invalid_scope)               \r\n                    AADSTS70011: The provided request must include a 'scope' input parameter. The               \r\n                    provided value for the input parameter 'scope' is not valid. The scope                      \r\n                    https://cognitiveservices.azure.com/ openid offline_access profile is not                   \r\n                    valid. The scope format is invalid. Scope must be in a valid URI form                       \r\n                    \\u003chttps://example/scope\\u003e or a valid Guid \\u003cguid/scope\\u003e.                   \r\n                    Trace ID: 90ec62ee-fc30-447e-a097-b8883cd25800 Correlation ID:                              \r\n                    6a064df5-461c-4dce-9354-e552ce9fa798 Timestamp: 2024-05-13 22:45:02Z\\n\\n\"}}                 \r\n                                                                                                                \r\n                    To mitigate this issue, please refer to the troubleshooting guidelines here                 \r\n                    at https://aka.ms/azsdk/python/identity/defaultazurecredential/troubleshoot.                \r\n           WARNING  DefaultAzureCredential failed to retrieve a token from the included           chained.py:123\r\n                    credentials.                                                                                \r\n                    Attempted credentials:                                                                      \r\n                            EnvironmentCredential: EnvironmentCredential authentication                         \r\n                    unavailable. Environment variables are not fully configured.                                \r\n                    Visit https://aka.ms/azsdk/python/identity/environmentcredential/troubleshoot               \r\n                    to troubleshoot this issue.                                                                 \r\n                            ManagedIdentityCredential: ManagedIdentityCredential authentication                 \r\n                    unavailable. The requested identity has not been assigned to this resource.                 \r\n                    Error: Unexpected response \"{'error': 'invalid_request', 'error_description':               \r\n                    'Identity not found'}\"                                                                      \r\n                            SharedTokenCacheCredential: SharedTokenCacheCredential authentication               \r\n                    unavailable. No accounts were found in the cache.                                           \r\n                            AzureCliCredential: Azure CLI not found on path                                     \r\n                            AzurePowerShellCredential: PowerShell is not installed                              \r\n                            AzureDeveloperCliCredential:                                                        \r\n                    {\"type\":\"consoleMessage\",\"timestamp\":\"2024-05-13T22:45:02.593558324Z\",\"data\":               \r\n                    {\"message\":\"\\nERROR: fetching token: failed to authenticate:\\n(invalid_scope)               \r\n                    AADSTS70011: The provided request must include a 'scope' input parameter. The               \r\n                    provided value for the input parameter 'scope' is not valid. The scope                      \r\n                    https://cognitiveservices.azure.com/ openid offline_access profile is not                   \r\n                    valid. The scope format is invalid. Scope must be in a valid URI form                       \r\n                    \\u003chttps://example/scope\\u003e or a valid Guid \\u003cguid/scope\\u003e.                   \r\n                    Trace ID: 9175eb02-a11c-464e-86cb-5642c8716600 Correlation ID:                              \r\n                    64131b49-df44-4386-8781-83bd7688020b Timestamp: 2024-05-13 22:45:02Z\\n\\n\"}}                 \r\n                                                                                                                \r\n                    To mitigate this issue, please refer to the troubleshooting guidelines here                 \r\n                    at https://aka.ms/azsdk/python/identity/defaultazurecredential/troubleshoot.                \r\n[22:45:05] WARNING  DefaultAzureCredential failed to retrieve a token from the included           chained.py:123\r\n                    credentials.                                                                                \r\n                    Attempted credentials:                                                                      \r\n                            EnvironmentCredential: EnvironmentCredential authentication                         \r\n                    unavailable. Environment variables are not fully configured.                                \r\n                    Visit https://aka.ms/azsdk/python/identity/environmentcredential/troubleshoot               \r\n                    to troubleshoot this issue.                                                                 \r\n                            ManagedIdentityCredential: ManagedIdentityCredential authentication                 \r\n                    unavailable. The requested identity has not been assigned to this resource.                 \r\n                    Error: Unexpected response \"{'error': 'invalid_request', 'error_description':               \r\n                    'Identity not found'}\"                                                                      \r\n                            SharedTokenCacheCredential: SharedTokenCacheCredential authentication               \r\n                    unavailable. No accounts were found in the cache.                                           \r\n                            AzureCliCredential: Azure CLI not found on path                                     \r\n                            AzurePowerShellCredential: PowerShell is not installed                              \r\n                            AzureDeveloperCliCredential:                                                        \r\n                    {\"type\":\"consoleMessage\",\"timestamp\":\"2024-05-13T22:45:05.920895603Z\",\"data\":               \r\n                    {\"message\":\"\\nERROR: fetching token: failed to authenticate:\\n(invalid_scope)               \r\n                    AADSTS70011: The provided request must include a 'scope' input parameter. The               \r\n                    provided value for the input parameter 'scope' is not valid. The scope                      \r\n                    https://cognitiveservices.azure.com/ openid offline_access profile is not                   \r\n                    valid. The scope format is invalid. Scope must be in a valid URI form                       \r\n                    \\u003chttps://example/scope\\u003e or a valid Guid \\u003cguid/scope\\u003e.                   \r\n                    Trace ID: 9ba8e8ea-8145-4f06-b234-8ae6a7b05e00 Correlation ID:                              \r\n                    3583cdf4-9218-47a4-aa45-af7529d9c1ed Timestamp: 2024-05-13 22:45:05Z\\n\\n\"}}                 \r\n                                                                                                                \r\n                    To mitigate this issue, please refer to the troubleshooting guidelines here                 \r\n                    at https://aka.ms/azsdk/python/identity/defaultazurecredential/troubleshoot.                \r\n[22:45:06] WARNING  DefaultAzureCredential failed to retrieve a token from the included           chained.py:123\r\n                    credentials.                                                                                \r\n                    Attempted credentials:                                                                      \r\n                            EnvironmentCredential: EnvironmentCredential authentication                         \r\n                    unavailable. Environment variables are not fully configured.                                \r\n                    Visit https://aka.ms/azsdk/python/identity/environmentcredential/troubleshoot               \r\n                    to troubleshoot this issue.                                                                 \r\n                            ManagedIdentityCredential: ManagedIdentityCredential authentication                 \r\n                    unavailable. The requested identity has not been assigned to this resource.                 \r\n                    Error: Unexpected response \"{'error': 'invalid_request', 'error_description':               \r\n                    'Identity not found'}\"                                                                      \r\n                            SharedTokenCacheCredential: SharedTokenCacheCredential authentication               \r\n                    unavailable. No accounts were found in the cache.                                           \r\n                            AzureCliCredential: Azure CLI not found on path                                     \r\n                            AzurePowerShellCredential: PowerShell is not installed                              \r\n                            AzureDeveloperCliCredential:                                                        \r\n                    {\"type\":\"consoleMessage\",\"timestamp\":\"2024-05-13T22:45:06.9722591Z\",\"data\":{\"               \r\n                    message\":\"\\nERROR: fetching token: failed to authenticate:\\n(invalid_scope)                 \r\n                    AADSTS70011: The provided request must include a 'scope' input parameter. The               \r\n                    provided value for the input parameter 'scope' is not valid. The scope                      \r\n                    https://cognitiveservices.azure.com/ openid offline_access profile is not                   \r\n                    valid. The scope format is invalid. Scope must be in a valid URI form                       \r\n                    \\u003chttps://example/scope\\u003e or a valid Guid \\u003cguid/scope\\u003e.                   \r\n                    Trace ID: f3bc8a18-e5f4-47c9-b4de-4c4ad1cd5400 Correlation ID:                              \r\n                    4ea32ae6-f7b4-464c-a01a-ce3471caa562 Timestamp: 2024-05-13 22:45:06Z\\n\\n\"}}                 \r\n                                                                                                                \r\n                    To mitigate this issue, please refer to the troubleshooting guidelines here                 \r\n                    at https://aka.ms/azsdk/python/identity/defaultazurecredential/troubleshoot.                \r\n[22:45:09] WARNING  DefaultAzureCredential failed to retrieve a token from the included           chained.py:123\r\n                    credentials.                                                                                \r\n                    Attempted credentials:                                                                      \r\n                            EnvironmentCredential: EnvironmentCredential authentication                         \r\n                    unavailable. Environment variables are not fully configured.                                \r\n                    Visit https://aka.ms/azsdk/python/identity/environmentcredential/troubleshoot               \r\n                    to troubleshoot this issue.                                                                 \r\n                            ManagedIdentityCredential: ManagedIdentityCredential authentication                 \r\n                    unavailable. The requested identity has not been assigned to this resource.                 \r\n                    Error: Unexpected response \"{'error': 'invalid_request', 'error_description':               \r\n                    'Identity not found'}\"                                                                      \r\n                            SharedTokenCacheCredential: SharedTokenCacheCredential authentication               \r\n                    unavailable. No accounts were found in the cache.                                           \r\n                            AzureCliCredential: Azure CLI not found on path                                     \r\n                            AzurePowerShellCredential: PowerShell is not installed                              \r\n                            AzureDeveloperCliCredential:                                                        \r\n                    {\"type\":\"consoleMessage\",\"timestamp\":\"2024-05-13T22:45:09.183899943Z\",\"data\":               \r\n                    {\"message\":\"\\nERROR: fetching token: failed to authenticate:\\n(invalid_scope)               \r\n                    AADSTS70011: The provided request must include a 'scope' input parameter. The               \r\n                    provided value for the input parameter 'scope' is not valid. The scope                      \r\n                    https://cognitiveservices.azure.com/ openid offline_access profile is not                   \r\n                    valid. The scope format is invalid. Scope must be in a valid URI form                       \r\n                    \\u003chttps://example/scope\\u003e or a valid Guid \\u003cguid/scope\\u003e.                   \r\n                    Trace ID: 72a4f6c6-e0c3-4fa7-8e23-c7cb14444f00 Correlation ID:                              \r\n                    0d471dd1-5f8d-4e20-8193-5181930da6b5 Timestamp: 2024-05-13 22:45:09Z\\n\\n\"}}                 \r\n                                                                                                                \r\n                    To mitigate this issue, please refer to the troubleshooting guidelines here                 \r\n                    at https://aka.ms/azsdk/python/identity/defaultazurecredential/troubleshoot.                \r\n[22:45:10] WARNING  DefaultAzureCredential failed to retrieve a token from the included           chained.py:123\r\n                    credentials.                                                                                \r\n                    Attempted credentials:                                                                      \r\n                            EnvironmentCredential: EnvironmentCredential authentication                         \r\n                    unavailable. Environment variables are not fully configured.                                \r\n                    Visit https://aka.ms/azsdk/python/identity/environmentcredential/troubleshoot               \r\n                    to troubleshoot this issue.                                                                 \r\n                            ManagedIdentityCredential: ManagedIdentityCredential authentication                 \r\n                    unavailable. The requested identity has not been assigned to this resource.                 \r\n                    Error: Unexpected response \"{'error': 'invalid_request', 'error_description':               \r\n                    'Identity not found'}\"                                                                      \r\n                            SharedTokenCacheCredential: SharedTokenCacheCredential authentication               \r\n                    unavailable. No accounts were found in the cache.                                           \r\n                            AzureCliCredential: Azure CLI not found on path                                     \r\n                            AzurePowerShellCredential: PowerShell is not installed                              \r\n                            AzureDeveloperCliCredential:                                                        \r\n                    {\"type\":\"consoleMessage\",\"timestamp\":\"2024-05-13T22:45:10.152382316Z\",\"data\":               \r\n                    {\"message\":\"\\nERROR: fetching token: failed to authenticate:\\n(invalid_scope)               \r\n                    AADSTS70011: The provided request must include a 'scope' input parameter. The               \r\n                    provided value for the input parameter 'scope' is not valid. The scope                      \r\n                    https://cognitiveservices.azure.com/ openid offline_access profile is not                   \r\n                    valid. The scope format is invalid. Scope must be in a valid URI form                       \r\n                    \\u003chttps://example/scope\\u003e or a valid Guid \\u003cguid/scope\\u003e.                   \r\n                    Trace ID: da7b4698-7ccd-4c23-a971-1fa78dbc7400 Correlation ID:                              \r\n                    332fe3da-4f22-4244-9a08-895c734ec079 Timestamp: 2024-05-13 22:45:10Z\\n\\n\"}}                 \r\n                                                                                                                \r\n                    To mitigate this issue, please refer to the troubleshooting guidelines here                 \r\n                    at https://aka.ms/azsdk/python/identity/defaultazurecredential/troubleshoot.                \r\n[22:45:14] WARNING  DefaultAzureCredential failed to retrieve a token from the included           chained.py:123\r\n                    credentials.                                                                                \r\n                    Attempted credentials:                                                                      \r\n                            EnvironmentCredential: EnvironmentCredential authentication                         \r\n                    unavailable. Environment variables are not fully configured.                                \r\n                    Visit https://aka.ms/azsdk/python/identity/environmentcredential/troubleshoot               \r\n                    to troubleshoot this issue.                                                                 \r\n                            ManagedIdentityCredential: ManagedIdentityCredential authentication                 \r\n                    unavailable. The requested identity has not been assigned to this resource.                 \r\n                    Error: Unexpected response \"{'error': 'invalid_request', 'error_description':               \r\n                    'Identity not found'}\"                                                                      \r\n                            SharedTokenCacheCredential: SharedTokenCacheCredential authentication               \r\n                    unavailable. No accounts were found in the cache.                                           \r\n                            AzureCliCredential: Azure CLI not found on path                                     \r\n                            AzurePowerShellCredential: PowerShell is not installed                              \r\n                            AzureDeveloperCliCredential:                                                        \r\n                    {\"type\":\"consoleMessage\",\"timestamp\":\"2024-05-13T22:45:14.587324371Z\",\"data\":               \r\n                    {\"message\":\"\\nERROR: fetching token: failed to authenticate:\\n(invalid_scope)               \r\n                    AADSTS70011: The provided request must include a 'scope' input parameter. The               \r\n                    provided value for the input parameter 'scope' is not valid. The scope                      \r\n                    https://cognitiveservices.azure.com/ openid offline_access profile is not                   \r\n                    valid. The scope format is invalid. Scope must be in a valid URI form                       \r\n                    \\u003chttps://example/scope\\u003e or a valid Guid \\u003cguid/scope\\u003e.                   \r\n                    Trace ID: 812f3b95-f0d4-42f6-90f3-0a6a25a45b00 Correlation ID:                              \r\n                    82126b7c-93c2-4c8e-a82d-5d98644160e4 Timestamp: 2024-05-13 22:45:14Z\\n\\n\"}}                 \r\n                                                                                                                \r\n                    To mitigate this issue, please refer to the troubleshooting guidelines here                 \r\n                    at https://aka.ms/azsdk/python/identity/defaultazurecredential/troubleshoot.                \r\n           WARNING  DefaultAzureCredential failed to retrieve a token from the included           chained.py:123\r\n                    credentials.                                                                                \r\n                    Attempted credentials:                                                                      \r\n                            EnvironmentCredential: EnvironmentCredential authentication                         \r\n                    unavailable. Environment variables are not fully configured.                                \r\n                    Visit https://aka.ms/azsdk/python/identity/environmentcredential/troubleshoot               \r\n                    to troubleshoot this issue.                                                                 \r\n                            ManagedIdentityCredential: ManagedIdentityCredential authentication                 \r\n                    unavailable. The requested identity has not been assigned to this resource.                 \r\n                    Error: Unexpected response \"{'error': 'invalid_request', 'error_description':               \r\n                    'Identity not found'}\"                                                                      \r\n                            SharedTokenCacheCredential: SharedTokenCacheCredential authentication               \r\n                    unavailable. No accounts were found in the cache.                                           \r\n                            AzureCliCredential: Azure CLI not found on path                                     \r\n                            AzurePowerShellCredential: PowerShell is not installed                              \r\n                            AzureDeveloperCliCredential:                                                        \r\n                    {\"type\":\"consoleMessage\",\"timestamp\":\"2024-05-13T22:45:14.629979902Z\",\"data\":               \r\n                    {\"message\":\"\\nERROR: fetching token: failed to authenticate:\\n(invalid_scope)               \r\n                    AADSTS70011: The provided request must include a 'scope' input parameter. The               \r\n                    provided value for the input parameter 'scope' is not valid. The scope                      \r\n                    https://cognitiveservices.azure.com/ openid offline_access profile is not                   \r\n                    valid. The scope format is invalid. Scope must be in a valid URI form                       \r\n                    \\u003chttps://example/scope\\u003e or a valid Guid \\u003cguid/scope\\u003e.                   \r\n                    Trace ID: 2de505a7-0a08-4b9b-a33f-01ebc94e6f00 Correlation ID:                              \r\n                    032e19b9-352d-421e-adc5-b59f83c7ed26 Timestamp: 2024-05-13 22:45:14Z\\n\\n\"}}                 \r\n                                                                                                                \r\n                    To mitigate this issue, please refer to the troubleshooting guidelines here                 \r\n                    at https://aka.ms/azsdk/python/identity/defaultazurecredential/troubleshoot.                \r\n           WARNING  DefaultAzureCredential failed to retrieve a token from the included           chained.py:123\r\n                    credentials.                                                                                \r\n                    Attempted credentials:                                                                      \r\n                            EnvironmentCredential: EnvironmentCredential authentication                         \r\n                    unavailable. Environment variables are not fully configured.                                \r\n                    Visit https://aka.ms/azsdk/python/identity/environmentcredential/troubleshoot               \r\n                    to troubleshoot this issue.                                                                 \r\n                            ManagedIdentityCredential: ManagedIdentityCredential authentication                 \r\n                    unavailable. The requested identity has not been assigned to this resource.                 \r\n                    Error: Unexpected response \"{'error': 'invalid_request', 'error_description':               \r\n                    'Identity not found'}\"                                                                      \r\n                            SharedTokenCacheCredential: SharedTokenCacheCredential authentication               \r\n                    unavailable. No accounts were found in the cache.                                           \r\n                            AzureCliCredential: Azure CLI not found on path                                     \r\n                            AzurePowerShellCredential: PowerShell is not installed                              \r\n                            AzureDeveloperCliCredential:                                                        \r\n                    {\"type\":\"consoleMessage\",\"timestamp\":\"2024-05-13T22:45:14.68679813Z\",\"data\":{               \r\n                    \"message\":\"\\nERROR: fetching token: failed to authenticate:\\n(invalid_scope)                \r\n                    AADSTS70011: The provided request must include a 'scope' input parameter. The               \r\n                    provided value for the input parameter 'scope' is not valid. The scope                      \r\n                    https://cognitiveservices.azure.com/ openid offline_access profile is not                   \r\n                    valid. The scope format is invalid. Scope must be in a valid URI form                       \r\n                    \\u003chttps://example/scope\\u003e or a valid Guid \\u003cguid/scope\\u003e.                   \r\n                    Trace ID: 2b6d94bd-5dfa-4de5-adbf-26eef5935000 Correlation ID:                              \r\n                    fbb61a5c-3945-4c0b-b0c7-29d2c4209b4c Timestamp: 2024-05-13 22:45:14Z\\n\\n\"}}                 \r\n                                                                                                                \r\n                    To mitigate this issue, please refer to the troubleshooting guidelines here                 \r\n                    at https://aka.ms/azsdk/python/identity/defaultazurecredential/troubleshoot.                \r\n[22:45:16] WARNING  DefaultAzureCredential failed to retrieve a token from the included           chained.py:123\r\n                    credentials.                                                                                \r\n                    Attempted credentials:                                                                      \r\n                            EnvironmentCredential: EnvironmentCredential authentication                         \r\n                    unavailable. Environment variables are not fully configured.                                \r\n                    Visit https://aka.ms/azsdk/python/identity/environmentcredential/troubleshoot               \r\n                    to troubleshoot this issue.                                                                 \r\n                            ManagedIdentityCredential: ManagedIdentityCredential authentication                 \r\n                    unavailable. The requested identity has not been assigned to this resource.                 \r\n                    Error: Unexpected response \"{'error': 'invalid_request', 'error_description':               \r\n                    'Identity not found'}\"                                                                      \r\n                            SharedTokenCacheCredential: SharedTokenCacheCredential authentication               \r\n                    unavailable. No accounts were found in the cache.                                           \r\n                            AzureCliCredential: Azure CLI not found on path                                     \r\n                            AzurePowerShellCredential: PowerShell is not installed                              \r\n                            AzureDeveloperCliCredential:                                                        \r\n                    {\"type\":\"consoleMessage\",\"timestamp\":\"2024-05-13T22:45:16.094273693Z\",\"data\":               \r\n                    {\"message\":\"\\nERROR: fetching token: failed to authenticate:\\n(invalid_scope)               \r\n                    AADSTS70011: The provided request must include a 'scope' input parameter. The               \r\n                    provided value for the input parameter 'scope' is not valid. The scope                      \r\n                    https://cognitiveservices.azure.com/ openid offline_access profile is not                   \r\n                    valid. The scope format is invalid. Scope must be in a valid URI form                       \r\n                    \\u003chttps://example/scope\\u003e or a valid Guid \\u003cguid/scope\\u003e.                   \r\n                    Trace ID: 9175eb02-a11c-464e-86cb-564244746600 Correlation ID:                              \r\n                    d516d97b-614c-4c79-b401-16ed0c2d1701 Timestamp: 2024-05-13 22:45:16Z\\n\\n\"}}                 \r\n                                                                                                                \r\n                    To mitigate this issue, please refer to the troubleshooting guidelines here                 \r\n                    at https://aka.ms/azsdk/python/identity/defaultazurecredential/troubleshoot.                \r\n[22:45:20] WARNING  DefaultAzureCredential failed to retrieve a token from the included           chained.py:123\r\n                    credentials.                                                                                \r\n                    Attempted credentials:                                                                      \r\n                            EnvironmentCredential: EnvironmentCredential authentication                         \r\n                    unavailable. Environment variables are not fully configured.                                \r\n                    Visit https://aka.ms/azsdk/python/identity/environmentcredential/troubleshoot               \r\n                    to troubleshoot this issue.                                                                 \r\n                            ManagedIdentityCredential: ManagedIdentityCredential authentication                 \r\n                    unavailable. The requested identity has not been assigned to this resource.                 \r\n                    Error: Unexpected response \"{'error': 'invalid_request', 'error_description':               \r\n                    'Identity not found'}\"                                                                      \r\n                            SharedTokenCacheCredential: SharedTokenCacheCredential authentication               \r\n                    unavailable. No accounts were found in the cache.                                           \r\n                            AzureCliCredential: Azure CLI not found on path                                     \r\n                            AzurePowerShellCredential: PowerShell is not installed                              \r\n                            AzureDeveloperCliCredential:                                                        \r\n                    {\"type\":\"consoleMessage\",\"timestamp\":\"2024-05-13T22:45:20.531998191Z\",\"data\":               \r\n                    {\"message\":\"\\nERROR: fetching token: failed to authenticate:\\n(invalid_scope)               \r\n                    AADSTS70011: The provided request must include a 'scope' input parameter. The               \r\n                    provided value for the input parameter 'scope' is not valid. The scope                      \r\n                    https://cognitiveservices.azure.com/ openid offline_access profile is not                   \r\n                    valid. The scope format is invalid. Scope must be in a valid URI form                       \r\n                    \\u003chttps://example/scope\\u003e or a valid Guid \\u003cguid/scope\\u003e.                   \r\n                    Trace ID: 451a61af-cf36-4f88-9194-1536ab515800 Correlation ID:                              \r\n                    4c65d9ed-12db-4f71-9033-3b743c28135c Timestamp: 2024-05-13 22:45:20Z\\n\\n\"}}                 \r\n                                                                                                                \r\n                    To mitigate this issue, please refer to the troubleshooting guidelines here                 \r\n                    at https://aka.ms/azsdk/python/identity/defaultazurecredential/troubleshoot.                \r\nTraceback (most recent call last):\r\n  File \"<frozen runpy>\", line 198, in _run_module_as_main\r\n  File \"<frozen runpy>\", line 88, in _run_code\r\n  File \"/workspaces/ai-rag-chat-evaluator/scripts/__main__.py\", line 6, in <module>\r\n    app()\r\n  File \"/home/vscode/.local/lib/python3.11/site-packages/typer/main.py\", line 326, in __call__\r\n    raise e\r\n  File \"/home/vscode/.local/lib/python3.11/site-packages/typer/main.py\", line 309, in __call__\r\n    return get_command(self)(*args, **kwargs)\r\n           ^^^^^^^^^^^^^^^^^^^^^^^^^^^^^^^^^^\r\n  File \"/home/vscode/.local/lib/python3.11/site-packages/click/core.py\", line 1157, in __call__\r\n    return self.main(*args, **kwargs)\r\n           ^^^^^^^^^^^^^^^^^^^^^^^^^^\r\n  File \"/home/vscode/.local/lib/python3.11/site-packages/typer/core.py\", line 723, in main\r\n    return _main(\r\n           ^^^^^^\r\n  File \"/home/vscode/.local/lib/python3.11/site-packages/typer/core.py\", line 193, in _main\r\n    rv = self.invoke(ctx)\r\n         ^^^^^^^^^^^^^^^^\r\n  File \"/home/vscode/.local/lib/python3.11/site-packages/click/core.py\", line 1688, in invoke\r\n    return _process_result(sub_ctx.command.invoke(sub_ctx))\r\n                           ^^^^^^^^^^^^^^^^^^^^^^^^^^^^^^^\r\n  File \"/home/vscode/.local/lib/python3.11/site-packages/click/core.py\", line 1434, in invoke\r\n    return ctx.invoke(self.callback, **ctx.params)\r\n           ^^^^^^^^^^^^^^^^^^^^^^^^^^^^^^^^^^^^^^^\r\n  File \"/home/vscode/.local/lib/python3.11/site-packages/click/core.py\", line 783, in invoke\r\n    return __callback(*args, **kwargs)\r\n           ^^^^^^^^^^^^^^^^^^^^^^^^^^^\r\n  File \"/home/vscode/.local/lib/python3.11/site-packages/typer/main.py\", line 692, in wrapper\r\n    return callback(**use_params)\r\n           ^^^^^^^^^^^^^^^^^^^^^^\r\n  File \"/workspaces/ai-rag-chat-evaluator/scripts/cli.py\", line 47, in evaluate\r\n    run_evaluate_from_config(Path.cwd(), config, numquestions, targeturl)\r\n  File \"/workspaces/ai-rag-chat-evaluator/scripts/evaluate.py\", line 214, in run_evaluate_from_config\r\n    evaluation_run_complete = run_evaluation(\r\n                              ^^^^^^^^^^^^^^^\r\n  File \"/workspaces/ai-rag-chat-evaluator/scripts/evaluate.py\", line 153, in run_evaluation\r\n    questions_with_ratings.append(future.result())\r\n                                  ^^^^^^^^^^^^^^^\r\n  File \"/usr/local/lib/python3.11/concurrent/futures/_base.py\", line 456, in result\r\n    return self.__get_result()\r\n           ^^^^^^^^^^^^^^^^^^^\r\n  File \"/usr/local/lib/python3.11/concurrent/futures/_base.py\", line 401, in __get_result\r\n    raise self._exception\r\n  File \"/usr/local/lib/python3.11/concurrent/futures/thread.py\", line 58, in run\r\n    result = self.fn(*self.args, **self.kwargs)\r\n             ^^^^^^^^^^^^^^^^^^^^^^^^^^^^^^^^^^\r\n  File \"/workspaces/ai-rag-chat-evaluator/scripts/evaluate.py\", line 135, in evaluate_row\r\n    result = metric.evaluator_fn(openai_config=openai_config)(\r\n             ^^^^^^^^^^^^^^^^^^^^^^^^^^^^^^^^^^^^^^^^^^^^^^^^^\r\n  File \"/home/vscode/.local/lib/python3.11/site-packages/promptflow/evals/evaluators/_groundedness/_groundedness.py\", line 56, in __call__\r\n    llm_output = self._flow(answer=answer, context=context)\r\n                 ^^^^^^^^^^^^^^^^^^^^^^^^^^^^^^^^^^^^^^^^^^\r\n  File \"/home/vscode/.local/lib/python3.11/site-packages/promptflow/_sdk/entities/_flows/prompty.py\", line 57, in __call__\r\n    return self._core_prompty(*args, **kwargs)\r\n           ^^^^^^^^^^^^^^^^^^^^^^^^^^^^^^^^^^^\r\n  File \"/home/vscode/.local/lib/python3.11/site-packages/promptflow/tracing/_trace.py\", line 469, in wrapped\r\n    output = func(*args, **kwargs)\r\n             ^^^^^^^^^^^^^^^^^^^^^\r\n  File \"/home/vscode/.local/lib/python3.11/site-packages/promptflow/core/_flow.py\", line 410, in __call__\r\n    response = send_request_to_llm(api_client, self._model.api, params)\r\n               ^^^^^^^^^^^^^^^^^^^^^^^^^^^^^^^^^^^^^^^^^^^^^^^^^^^^^^^^\r\n  File \"/home/vscode/.local/lib/python3.11/site-packages/promptflow/core/_prompty_utils.py\", line 164, in send_request_to_llm\r\n    result = client.chat.completions.create(**parameters)\r\n             ^^^^^^^^^^^^^^^^^^^^^^^^^^^^^^^^^^^^^^^^^^^^\r\n  File \"/home/vscode/.local/lib/python3.11/site-packages/openai/_utils/_utils.py\", line 277, in wrapper\r\n    return func(*args, **kwargs)\r\n           ^^^^^^^^^^^^^^^^^^^^^\r\n  File \"/home/vscode/.local/lib/python3.11/site-packages/openai/resources/chat/completions.py\", line 590, in create\r\n    return self._post(\r\n           ^^^^^^^^^^^\r\n  File \"/home/vscode/.local/lib/python3.11/site-packages/openai/_base_client.py\", line 1240, in post\r\n    return cast(ResponseT, self.request(cast_to, opts, stream=stream, stream_cls=stream_cls))\r\n                           ^^^^^^^^^^^^^^^^^^^^^^^^^^^^^^^^^^^^^^^^^^^^^^^^^^^^^^^^^^^^^^^^^\r\n  File \"/home/vscode/.local/lib/python3.11/site-packages/openai/_base_client.py\", line 921, in request\r\n    return self._request(\r\n           ^^^^^^^^^^^^^^\r\n  File \"/home/vscode/.local/lib/python3.11/site-packages/openai/_base_client.py\", line 939, in _request\r\n    self._prepare_options(options)\r\n  File \"/home/vscode/.local/lib/python3.11/site-packages/openai/lib/azure.py\", line 288, in _prepare_options\r\n    azure_ad_token = self._get_azure_ad_token()\r\n                     ^^^^^^^^^^^^^^^^^^^^^^^^^^\r\n  File \"/home/vscode/.local/lib/python3.11/site-packages/openai/lib/azure.py\", line 274, in _get_azure_ad_token\r\n    token = provider()\r\n            ^^^^^^^^^^\r\n  File \"/home/vscode/.local/lib/python3.11/site-packages/promptflow/core/_connection.py\", line 247, in get_token\r\n    return self._token_provider.get_token()\r\n           ^^^^^^^^^^^^^^^^^^^^^^^^^^^^^^^^\r\n  File \"/home/vscode/.local/lib/python3.11/site-packages/promptflow/_core/token_provider.py\", line 52, in get_token\r\n    return self.credential.get_token(audience).token\r\n           ^^^^^^^^^^^^^^^^^^^^^^^^^^^^^^^^^^^\r\n  File \"/home/vscode/.local/lib/python3.11/site-packages/azure/identity/_credentials/default.py\", line 225, in get_token\r\n    token = super().get_token(*scopes, claims=claims, tenant_id=tenant_id, **kwargs)\r\n            ^^^^^^^^^^^^^^^^^^^^^^^^^^^^^^^^^^^^^^^^^^^^^^^^^^^^^^^^^^^^^^^^^^^^^^^^\r\n  File \"/home/vscode/.local/lib/python3.11/site-packages/azure/identity/_credentials/chained.py\", line 124, in get_token\r\n    raise ClientAuthenticationError(message=message)\r\nazure.core.exceptions.ClientAuthenticationError: DefaultAzureCredential failed to retrieve a token from the included credentials.\r\nAttempted credentials:\r\n        EnvironmentCredential: EnvironmentCredential authentication unavailable. Environment variables are not fully configured.\r\nVisit https://aka.ms/azsdk/python/identity/environmentcredential/troubleshoot to troubleshoot this issue.\r\n        ManagedIdentityCredential: ManagedIdentityCredential authentication unavailable. The requested identity has not been assigned to this resource. Error: Unexpected response \"{'error': 'invalid_request', 'error_description': 'Identity not found'}\"\r\n        SharedTokenCacheCredential: SharedTokenCacheCredential authentication unavailable. No accounts were found in the cache.\r\n        AzureCliCredential: Azure CLI not found on path\r\n        AzurePowerShellCredential: PowerShell is not installed\r\n        AzureDeveloperCliCredential: {\"type\":\"consoleMessage\",\"timestamp\":\"2024-05-13T22:45:02.593558324Z\",\"data\":{\"message\":\"\\nERROR: fetching token: failed to authenticate:\\n(invalid_scope) AADSTS70011: The provided request must include a 'scope' input parameter. The provided value for the input parameter 'scope' is not valid. The scope https://cognitiveservices.azure.com/ openid offline_access profile is not valid. The scope format is invalid. Scope must be in a valid URI form \\u003chttps://example/scope\\u003e or a valid Guid \\u003cguid/scope\\u003e. Trace ID: 9175eb02-a11c-464e-86cb-5642c8716600 Correlation ID: 64131b49-df44-4386-8781-83bd7688020b Timestamp: 2024-05-13 22:45:02Z\\n\\n\"}}\r\n\r\nTo mitigate this issue, please refer to the troubleshooting guidelines here at https://aka.ms/azsdk/python/identity/defaultazurecredential/troubleshoot.\r\n```\r\n\r\n6. To fix, tried to add azd env for az cli: `azd config set auth.useAzCliAuth \"true\"` then `azd auth login` again and az cli isn't in repo. \r\n\r\n### Any log messages given by the failure\r\n>\r\n\r\n### Expected/desired behavior\r\n>\r\n\r\n### OS and Version?\r\n> Windows 7, 8 or 10. Linux (which distribution). macOS (Yosemite? El Capitan? Sierra?)\r\n\r\n### Versions\r\n>\r\n\r\n### Mention any other details that might be useful\r\n\r\n> ---------------------------------------------------------------\r\n> Thanks! We'll be in touch soon.\r\n\r\n\r\n",
          "reactions": {
            "url": "https://api.github.com/repos/Azure-Samples/ai-rag-chat-evaluator/issues/87/reactions",
            "total_count": 0,
            "+1": 0,
            "-1": 0,
            "laugh": 0,
            "hooray": 0,
            "confused": 0,
            "heart": 0,
            "rocket": 0,
            "eyes": 0
          },
          "timeline_url": "https://api.github.com/repos/Azure-Samples/ai-rag-chat-evaluator/issues/87/timeline",
          "performed_via_github_app": null,
          "state_reason": null,
          "score": 1
        }
      ]
    }
  },
  {
    "dateRange": {
      "start": "2024-05-13",
      "end": "2024-05-13"
    },
    "url": "https://api.github.com/search/issues?q=involves:dfberry+created:2024-05-13..2024-05-13",
    "user": "dfberry",
    "results": {
      "total_count": 0,
      "incomplete_results": false,
      "items": []
    }
  },
  {
    "dateRange": {
      "start": "2024-05-13",
      "end": "2024-05-13"
    },
    "url": "https://api.github.com/search/issues?q=reviewed-by:diberry+created:2024-05-13..2024-05-13",
    "user": "diberry",
    "results": {
      "total_count": 0,
      "incomplete_results": false,
      "items": []
    }
  },
  {
    "dateRange": {
      "start": "2024-05-13",
      "end": "2024-05-13"
    },
    "url": "https://api.github.com/search/issues?q=reviewed-by:dfberry+created:2024-05-13..2024-05-13",
    "user": "dfberry",
    "results": {
      "total_count": 0,
      "incomplete_results": false,
      "items": []
    }
  },
  {
    "dateRange": {
      "start": "2024-05-13",
      "end": "2024-05-13"
    },
    "url": "https://api.github.com/search/issues?q=assignee:diberry+created:2024-05-13..2024-05-13",
    "user": "diberry",
    "results": {
      "total_count": 0,
      "incomplete_results": false,
      "items": []
    }
  },
  {
    "dateRange": {
      "start": "2024-05-13",
      "end": "2024-05-13"
    },
    "url": "https://api.github.com/search/issues?q=assignee:dfberry+created:2024-05-13..2024-05-13",
    "user": "dfberry",
    "results": {
      "total_count": 0,
      "incomplete_results": false,
      "items": []
    }
  }
]